[2022-11-22 04:02:31,742] {taskinstance.py:1159} INFO - Dependencies all met for <TaskInstance: etl_solar.load_files.extract_geography_info scheduled__2022-11-21T00:00:00+00:00 [queued]>
[2022-11-22 04:02:31,787] {taskinstance.py:1159} INFO - Dependencies all met for <TaskInstance: etl_solar.load_files.extract_geography_info scheduled__2022-11-21T00:00:00+00:00 [queued]>
[2022-11-22 04:02:31,789] {taskinstance.py:1356} INFO - 
--------------------------------------------------------------------------------
[2022-11-22 04:02:31,790] {taskinstance.py:1357} INFO - Starting attempt 1 of 1
[2022-11-22 04:02:31,791] {taskinstance.py:1358} INFO - 
--------------------------------------------------------------------------------
[2022-11-22 04:02:31,861] {taskinstance.py:1377} INFO - Executing <Task(PythonOperator): load_files.extract_geography_info> on 2022-11-21 00:00:00+00:00
[2022-11-22 04:02:31,873] {standard_task_runner.py:52} INFO - Started process 137 to run task
[2022-11-22 04:02:31,888] {standard_task_runner.py:79} INFO - Running: ['***', 'tasks', 'run', 'etl_solar', 'load_files.extract_geography_info', 'scheduled__2022-11-21T00:00:00+00:00', '--job-id', '143', '--raw', '--subdir', 'DAGS_FOLDER/dag_preprocess.py', '--cfg-path', '/tmp/tmpcrg8w9e4', '--error-file', '/tmp/tmpexpktsgg']
[2022-11-22 04:02:31,892] {standard_task_runner.py:80} INFO - Job 143: Subtask load_files.extract_geography_info
[2022-11-22 04:02:31,947] {warnings.py:110} WARNING - /home/***/.local/lib/python3.7/site-packages/***/configuration.py:470: DeprecationWarning: The sql_alchemy_conn option in [core] has been moved to the sql_alchemy_conn option in [database] - the old setting has been used, but please update your config.
  option = self._get_environment_variables(deprecated_key, deprecated_section, key, section)

[2022-11-22 04:02:32,140] {task_command.py:369} INFO - Running <TaskInstance: etl_solar.load_files.extract_geography_info scheduled__2022-11-21T00:00:00+00:00 [running]> on host 8a647070b091
[2022-11-22 04:02:32,564] {taskinstance.py:1571} INFO - Exporting the following env vars:
AIRFLOW_CTX_DAG_OWNER=***
AIRFLOW_CTX_DAG_ID=etl_solar
AIRFLOW_CTX_TASK_ID=load_files.extract_geography_info
AIRFLOW_CTX_EXECUTION_DATE=2022-11-21T00:00:00+00:00
AIRFLOW_CTX_TRY_NUMBER=1
AIRFLOW_CTX_DAG_RUN_ID=scheduled__2022-11-21T00:00:00+00:00
[2022-11-22 04:02:32,569] {taskinstance.py:1889} ERROR - Task failed with exception
Traceback (most recent call last):
  File "/home/airflow/.local/lib/python3.7/site-packages/airflow/operators/python.py", line 171, in execute
    return_value = self.execute_callable()
  File "/home/airflow/.local/lib/python3.7/site-packages/airflow/operators/python.py", line 189, in execute_callable
    return self.python_callable(*self.op_args, **self.op_kwargs)
  File "/opt/airflow/dags/preprocess/connection.py", line 12, in inner_function
    return function(**kwargs)
  File "/opt/airflow/dags/groups/group_loads.py", line 20, in save_data
    sql_data=context['mysqlServer'].get_pandas_df(sql=['params']['sql'])
TypeError: list indices must be integers or slices, not str
[2022-11-22 04:02:32,634] {taskinstance.py:1400} INFO - Marking task as FAILED. dag_id=etl_solar, task_id=load_files.extract_geography_info, execution_date=20221121T000000, start_date=20221122T040231, end_date=20221122T040232
[2022-11-22 04:02:32,693] {standard_task_runner.py:97} ERROR - Failed to execute job 143 for task load_files.extract_geography_info (list indices must be integers or slices, not str; 137)
[2022-11-22 04:02:32,745] {local_task_job.py:156} INFO - Task exited with return code 1
[2022-11-22 04:02:32,888] {local_task_job.py:273} INFO - 0 downstream tasks scheduled from follow-on schedule check
[2022-11-22 04:12:51,725] {taskinstance.py:1159} INFO - Dependencies all met for <TaskInstance: etl_solar.load_files.extract_geography_info scheduled__2022-11-21T00:00:00+00:00 [queued]>
[2022-11-22 04:12:51,781] {taskinstance.py:1159} INFO - Dependencies all met for <TaskInstance: etl_solar.load_files.extract_geography_info scheduled__2022-11-21T00:00:00+00:00 [queued]>
[2022-11-22 04:12:51,783] {taskinstance.py:1356} INFO - 
--------------------------------------------------------------------------------
[2022-11-22 04:12:51,784] {taskinstance.py:1357} INFO - Starting attempt 1 of 1
[2022-11-22 04:12:51,785] {taskinstance.py:1358} INFO - 
--------------------------------------------------------------------------------
[2022-11-22 04:12:51,913] {taskinstance.py:1377} INFO - Executing <Task(PythonOperator): load_files.extract_geography_info> on 2022-11-21 00:00:00+00:00
[2022-11-22 04:12:51,935] {standard_task_runner.py:52} INFO - Started process 185 to run task
[2022-11-22 04:12:51,954] {standard_task_runner.py:79} INFO - Running: ['***', 'tasks', 'run', 'etl_solar', 'load_files.extract_geography_info', 'scheduled__2022-11-21T00:00:00+00:00', '--job-id', '157', '--raw', '--subdir', 'DAGS_FOLDER/dag_preprocess.py', '--cfg-path', '/tmp/tmpbh7z0pq1', '--error-file', '/tmp/tmpxfg_zb_u']
[2022-11-22 04:12:51,960] {standard_task_runner.py:80} INFO - Job 157: Subtask load_files.extract_geography_info
[2022-11-22 04:12:52,172] {warnings.py:110} WARNING - /home/***/.local/lib/python3.7/site-packages/***/configuration.py:470: DeprecationWarning: The sql_alchemy_conn option in [core] has been moved to the sql_alchemy_conn option in [database] - the old setting has been used, but please update your config.
  option = self._get_environment_variables(deprecated_key, deprecated_section, key, section)

[2022-11-22 04:12:52,473] {task_command.py:369} INFO - Running <TaskInstance: etl_solar.load_files.extract_geography_info scheduled__2022-11-21T00:00:00+00:00 [running]> on host 8a647070b091
[2022-11-22 04:12:52,957] {taskinstance.py:1571} INFO - Exporting the following env vars:
AIRFLOW_CTX_DAG_OWNER=***
AIRFLOW_CTX_DAG_ID=etl_solar
AIRFLOW_CTX_TASK_ID=load_files.extract_geography_info
AIRFLOW_CTX_EXECUTION_DATE=2022-11-21T00:00:00+00:00
AIRFLOW_CTX_TRY_NUMBER=1
AIRFLOW_CTX_DAG_RUN_ID=scheduled__2022-11-21T00:00:00+00:00
[2022-11-22 04:12:53,008] {base.py:68} INFO - Using connection ID 'mysql_solar' for task execution.
[2022-11-22 04:12:53,152] {taskinstance.py:1889} ERROR - Task failed with exception
Traceback (most recent call last):
  File "/home/airflow/.local/lib/python3.7/site-packages/airflow/operators/python.py", line 171, in execute
    return_value = self.execute_callable()
  File "/home/airflow/.local/lib/python3.7/site-packages/airflow/operators/python.py", line 189, in execute_callable
    return self.python_callable(*self.op_args, **self.op_kwargs)
  File "/opt/airflow/dags/preprocess/connection.py", line 12, in inner_function
    return function(**kwargs)
  File "/opt/airflow/dags/groups/group_loads.py", line 22, in save_data
    sql_data.to_csv(context['params']['dest_path'])
  File "/home/airflow/.local/lib/python3.7/site-packages/pandas/core/generic.py", line 3482, in to_csv
    storage_options=storage_options,
  File "/home/airflow/.local/lib/python3.7/site-packages/pandas/io/formats/format.py", line 1105, in to_csv
    csv_formatter.save()
  File "/home/airflow/.local/lib/python3.7/site-packages/pandas/io/formats/csvs.py", line 243, in save
    storage_options=self.storage_options,
  File "/home/airflow/.local/lib/python3.7/site-packages/pandas/io/common.py", line 707, in get_handle
    newline="",
FileNotFoundError: [Errno 2] No such file or directory: '/opt/airflow/storage/input/2022-11-22/geography.csv'
[2022-11-22 04:12:53,245] {taskinstance.py:1400} INFO - Marking task as FAILED. dag_id=etl_solar, task_id=load_files.extract_geography_info, execution_date=20221121T000000, start_date=20221122T041251, end_date=20221122T041253
[2022-11-22 04:12:53,360] {standard_task_runner.py:97} ERROR - Failed to execute job 157 for task load_files.extract_geography_info ([Errno 2] No such file or directory: '/opt/airflow/storage/input/2022-11-22/geography.csv'; 185)
[2022-11-22 04:12:53,415] {local_task_job.py:156} INFO - Task exited with return code 1
[2022-11-22 04:12:53,635] {local_task_job.py:273} INFO - 0 downstream tasks scheduled from follow-on schedule check
