[2022-12-04 06:10:42,476] {taskinstance.py:1159} INFO - Dependencies all met for <TaskInstance: etl_solar.checkfiles.check_solar_table scheduled__2022-12-03T00:00:00+00:00 [queued]>
[2022-12-04 06:10:42,663] {taskinstance.py:1159} INFO - Dependencies all met for <TaskInstance: etl_solar.checkfiles.check_solar_table scheduled__2022-12-03T00:00:00+00:00 [queued]>
[2022-12-04 06:10:42,669] {taskinstance.py:1356} INFO - 
--------------------------------------------------------------------------------
[2022-12-04 06:10:42,678] {taskinstance.py:1357} INFO - Starting attempt 1 of 1
[2022-12-04 06:10:42,680] {taskinstance.py:1358} INFO - 
--------------------------------------------------------------------------------
[2022-12-04 06:10:42,820] {taskinstance.py:1377} INFO - Executing <Task(MySqlOperator): checkfiles.check_solar_table> on 2022-12-03 00:00:00+00:00
[2022-12-04 06:10:42,860] {standard_task_runner.py:52} INFO - Started process 63 to run task
[2022-12-04 06:10:42,895] {standard_task_runner.py:79} INFO - Running: ['***', 'tasks', 'run', 'etl_solar', 'checkfiles.check_solar_table', 'scheduled__2022-12-03T00:00:00+00:00', '--job-id', '295', '--raw', '--subdir', 'DAGS_FOLDER/dag_preprocess.py', '--cfg-path', '/tmp/tmp8mtb6op6', '--error-file', '/tmp/tmp031xxcbr']
[2022-12-04 06:10:42,902] {standard_task_runner.py:80} INFO - Job 295: Subtask checkfiles.check_solar_table
[2022-12-04 06:10:43,005] {warnings.py:110} WARNING - /home/***/.local/lib/python3.7/site-packages/***/configuration.py:470: DeprecationWarning: The sql_alchemy_conn option in [core] has been moved to the sql_alchemy_conn option in [database] - the old setting has been used, but please update your config.
  option = self._get_environment_variables(deprecated_key, deprecated_section, key, section)

[2022-12-04 06:10:43,583] {task_command.py:369} INFO - Running <TaskInstance: etl_solar.checkfiles.check_solar_table scheduled__2022-12-03T00:00:00+00:00 [running]> on host 8a647070b091
[2022-12-04 06:10:44,708] {taskinstance.py:1571} INFO - Exporting the following env vars:
AIRFLOW_CTX_DAG_OWNER=***
AIRFLOW_CTX_DAG_ID=etl_solar
AIRFLOW_CTX_TASK_ID=checkfiles.check_solar_table
AIRFLOW_CTX_EXECUTION_DATE=2022-12-03T00:00:00+00:00
AIRFLOW_CTX_TRY_NUMBER=1
AIRFLOW_CTX_DAG_RUN_ID=scheduled__2022-12-03T00:00:00+00:00
[2022-12-04 06:10:44,716] {mysql.py:82} INFO - Executing: 


CREATE TABLE IF NOT EXISTS geography(
                locdate VARCHAR(40),
                location VARCHAR(40),
                updated_date CHAR(10),
                altitudeMeridian VARCHAR(13),
                altitude_09 VARCHAR(20),
                altitude_12 VARCHAR(20),
                altitude_15 VARCHAR(20),
                altitude_18 VARCHAR(20),
                azimuth_09 VARCHAR(20),
                azimuth_12 VARCHAR(20),
                azimuth_15 VARCHAR(20),
                azimuth_18 VARCHAR(20),
                primary key(locdate,location))
[2022-12-04 06:10:44,792] {base.py:68} INFO - Using connection ID 'mysql_solar' for task execution.
[2022-12-04 06:10:46,905] {taskinstance.py:1889} ERROR - Task failed with exception
Traceback (most recent call last):
  File "/home/airflow/.local/lib/python3.7/site-packages/airflow/providers/mysql/operators/mysql.py", line 84, in execute
    hook.run(self.sql, autocommit=self.autocommit, parameters=self.parameters)
  File "/home/airflow/.local/lib/python3.7/site-packages/airflow/hooks/dbapi.py", line 181, in run
    with closing(self.get_conn()) as conn:
  File "/home/airflow/.local/lib/python3.7/site-packages/airflow/providers/mysql/hooks/mysql.py", line 166, in get_conn
    return MySQLdb.connect(**conn_config)
  File "/home/airflow/.local/lib/python3.7/site-packages/MySQLdb/__init__.py", line 123, in Connect
    return Connection(*args, **kwargs)
  File "/home/airflow/.local/lib/python3.7/site-packages/MySQLdb/connections.py", line 185, in __init__
    super().__init__(*args, **kwargs2)
MySQLdb._exceptions.OperationalError: (2003, "Can't connect to MySQL server on 'host.docker.internal:3306' (111)")
[2022-12-04 06:10:46,998] {taskinstance.py:1400} INFO - Marking task as FAILED. dag_id=etl_solar, task_id=checkfiles.check_solar_table, execution_date=20221203T000000, start_date=20221204T061042, end_date=20221204T061046
[2022-12-04 06:10:47,083] {standard_task_runner.py:97} ERROR - Failed to execute job 295 for task checkfiles.check_solar_table ((2003, "Can't connect to MySQL server on 'host.docker.internal:3306' (111)"); 63)
[2022-12-04 06:10:47,159] {local_task_job.py:156} INFO - Task exited with return code 1
[2022-12-04 06:10:47,631] {local_task_job.py:273} INFO - 0 downstream tasks scheduled from follow-on schedule check
