[2022-11-22 04:12:41,781] {taskinstance.py:1159} INFO - Dependencies all met for <TaskInstance: etl_solar.load_files.extract_weather_info manual__2022-11-22T04:12:25.215129+00:00 [queued]>
[2022-11-22 04:12:41,857] {taskinstance.py:1159} INFO - Dependencies all met for <TaskInstance: etl_solar.load_files.extract_weather_info manual__2022-11-22T04:12:25.215129+00:00 [queued]>
[2022-11-22 04:12:41,859] {taskinstance.py:1356} INFO - 
--------------------------------------------------------------------------------
[2022-11-22 04:12:41,861] {taskinstance.py:1357} INFO - Starting attempt 1 of 1
[2022-11-22 04:12:41,863] {taskinstance.py:1358} INFO - 
--------------------------------------------------------------------------------
[2022-11-22 04:12:41,977] {taskinstance.py:1377} INFO - Executing <Task(PythonOperator): load_files.extract_weather_info> on 2022-11-22 04:12:25.215129+00:00
[2022-11-22 04:12:41,994] {standard_task_runner.py:52} INFO - Started process 171 to run task
[2022-11-22 04:12:42,033] {standard_task_runner.py:79} INFO - Running: ['***', 'tasks', 'run', 'etl_solar', 'load_files.extract_weather_info', 'manual__2022-11-22T04:12:25.215129+00:00', '--job-id', '154', '--raw', '--subdir', 'DAGS_FOLDER/dag_preprocess.py', '--cfg-path', '/tmp/tmpdgoubkob', '--error-file', '/tmp/tmpqzpnfz3j']
[2022-11-22 04:12:42,040] {standard_task_runner.py:80} INFO - Job 154: Subtask load_files.extract_weather_info
[2022-11-22 04:12:42,632] {task_command.py:369} INFO - Running <TaskInstance: etl_solar.load_files.extract_weather_info manual__2022-11-22T04:12:25.215129+00:00 [running]> on host 8a647070b091
[2022-11-22 04:12:43,293] {taskinstance.py:1571} INFO - Exporting the following env vars:
AIRFLOW_CTX_DAG_OWNER=***
AIRFLOW_CTX_DAG_ID=etl_solar
AIRFLOW_CTX_TASK_ID=load_files.extract_weather_info
AIRFLOW_CTX_EXECUTION_DATE=2022-11-22T04:12:25.215129+00:00
AIRFLOW_CTX_TRY_NUMBER=1
AIRFLOW_CTX_DAG_RUN_ID=manual__2022-11-22T04:12:25.215129+00:00
[2022-11-22 04:12:43,380] {base.py:68} INFO - Using connection ID 'mysql_solar' for task execution.
[2022-11-22 04:12:43,594] {taskinstance.py:1889} ERROR - Task failed with exception
Traceback (most recent call last):
  File "/home/airflow/.local/lib/python3.7/site-packages/airflow/operators/python.py", line 171, in execute
    return_value = self.execute_callable()
  File "/home/airflow/.local/lib/python3.7/site-packages/airflow/operators/python.py", line 189, in execute_callable
    return self.python_callable(*self.op_args, **self.op_kwargs)
  File "/opt/airflow/dags/preprocess/connection.py", line 12, in inner_function
    return function(**kwargs)
  File "/opt/airflow/dags/groups/group_loads.py", line 22, in save_data
    sql_data.to_csv(context['params']['dest_path'])
  File "/home/airflow/.local/lib/python3.7/site-packages/pandas/core/generic.py", line 3482, in to_csv
    storage_options=storage_options,
  File "/home/airflow/.local/lib/python3.7/site-packages/pandas/io/formats/format.py", line 1105, in to_csv
    csv_formatter.save()
  File "/home/airflow/.local/lib/python3.7/site-packages/pandas/io/formats/csvs.py", line 243, in save
    storage_options=self.storage_options,
  File "/home/airflow/.local/lib/python3.7/site-packages/pandas/io/common.py", line 707, in get_handle
    newline="",
FileNotFoundError: [Errno 2] No such file or directory: '/opt/airflow/storage/input/2022-11-22/weather.csv'
[2022-11-22 04:12:43,734] {taskinstance.py:1400} INFO - Marking task as FAILED. dag_id=etl_solar, task_id=load_files.extract_weather_info, execution_date=20221122T041225, start_date=20221122T041241, end_date=20221122T041243
[2022-11-22 04:12:43,834] {standard_task_runner.py:97} ERROR - Failed to execute job 154 for task load_files.extract_weather_info ([Errno 2] No such file or directory: '/opt/airflow/storage/input/2022-11-22/weather.csv'; 171)
[2022-11-22 04:12:43,902] {local_task_job.py:156} INFO - Task exited with return code 1
[2022-11-22 04:12:44,115] {local_task_job.py:273} INFO - 0 downstream tasks scheduled from follow-on schedule check
