[2022-11-22 05:02:38,613] {taskinstance.py:1159} INFO - Dependencies all met for <TaskInstance: etl_solar.weather_transform.preprocess_weather manual__2022-11-22T05:02:17.023684+00:00 [queued]>
[2022-11-22 05:02:38,658] {taskinstance.py:1159} INFO - Dependencies all met for <TaskInstance: etl_solar.weather_transform.preprocess_weather manual__2022-11-22T05:02:17.023684+00:00 [queued]>
[2022-11-22 05:02:38,659] {taskinstance.py:1356} INFO - 
--------------------------------------------------------------------------------
[2022-11-22 05:02:38,660] {taskinstance.py:1357} INFO - Starting attempt 1 of 1
[2022-11-22 05:02:38,662] {taskinstance.py:1358} INFO - 
--------------------------------------------------------------------------------
[2022-11-22 05:02:38,725] {taskinstance.py:1377} INFO - Executing <Task(PythonOperator): weather_transform.preprocess_weather> on 2022-11-22 05:02:17.023684+00:00
[2022-11-22 05:02:38,740] {standard_task_runner.py:52} INFO - Started process 382 to run task
[2022-11-22 05:02:38,756] {standard_task_runner.py:79} INFO - Running: ['***', 'tasks', 'run', 'etl_solar', 'weather_transform.preprocess_weather', 'manual__2022-11-22T05:02:17.023684+00:00', '--job-id', '211', '--raw', '--subdir', 'DAGS_FOLDER/dag_preprocess.py', '--cfg-path', '/tmp/tmpon0b_13n', '--error-file', '/tmp/tmpa_a97vbv']
[2022-11-22 05:02:38,760] {standard_task_runner.py:80} INFO - Job 211: Subtask weather_transform.preprocess_weather
[2022-11-22 05:02:39,007] {task_command.py:369} INFO - Running <TaskInstance: etl_solar.weather_transform.preprocess_weather manual__2022-11-22T05:02:17.023684+00:00 [running]> on host 8a647070b091
[2022-11-22 05:02:39,335] {taskinstance.py:1571} INFO - Exporting the following env vars:
AIRFLOW_CTX_DAG_OWNER=***
AIRFLOW_CTX_DAG_ID=etl_solar
AIRFLOW_CTX_TASK_ID=weather_transform.preprocess_weather
AIRFLOW_CTX_EXECUTION_DATE=2022-11-22T05:02:17.023684+00:00
AIRFLOW_CTX_TRY_NUMBER=1
AIRFLOW_CTX_DAG_RUN_ID=manual__2022-11-22T05:02:17.023684+00:00
[2022-11-22 05:02:39,379] {taskinstance.py:1889} ERROR - Task failed with exception
Traceback (most recent call last):
  File "/home/airflow/.local/lib/python3.7/site-packages/airflow/operators/python.py", line 171, in execute
    return_value = self.execute_callable()
  File "/home/airflow/.local/lib/python3.7/site-packages/airflow/operators/python.py", line 189, in execute_callable
    return self.python_callable(*self.op_args, **self.op_kwargs)
  File "/opt/airflow/dags/preprocess/preprocess.py", line 49, in weather_preprocess
    df['Forecast_Time']=df.apply(lambda x:extract_stamp(x['locdatetime']),axis=1)
  File "/home/airflow/.local/lib/python3.7/site-packages/pandas/core/frame.py", line 8740, in apply
    return op.apply()
  File "/home/airflow/.local/lib/python3.7/site-packages/pandas/core/apply.py", line 688, in apply
    return self.apply_standard()
  File "/home/airflow/.local/lib/python3.7/site-packages/pandas/core/apply.py", line 812, in apply_standard
    results, res_index = self.apply_series_generator()
  File "/home/airflow/.local/lib/python3.7/site-packages/pandas/core/apply.py", line 828, in apply_series_generator
    results[i] = self.f(v)
  File "/opt/airflow/dags/preprocess/preprocess.py", line 49, in <lambda>
    df['Forecast_Time']=df.apply(lambda x:extract_stamp(x['locdatetime']),axis=1)
  File "/opt/airflow/dags/preprocess/preprocess.py", line 7, in extract_stamp
    data=re.search("fmt:'?([0-9]{,4})'?\s*mft:'?([0-9]{,2})'?\s*dft:'?([0-9]{,2})'?\s*T([\d]{,2}:[\d]{,2}:[\d]{,2})",data).groups()
UnboundLocalError: local variable 'data' referenced before assignment
[2022-11-22 05:02:39,444] {taskinstance.py:1400} INFO - Marking task as FAILED. dag_id=etl_solar, task_id=weather_transform.preprocess_weather, execution_date=20221122T050217, start_date=20221122T050238, end_date=20221122T050239
[2022-11-22 05:02:39,494] {standard_task_runner.py:97} ERROR - Failed to execute job 211 for task weather_transform.preprocess_weather (local variable 'data' referenced before assignment; 382)
[2022-11-22 05:02:39,532] {local_task_job.py:156} INFO - Task exited with return code 1
[2022-11-22 05:02:39,673] {local_task_job.py:273} INFO - 0 downstream tasks scheduled from follow-on schedule check
