[2022-12-11T08:18:03.846+0000] {taskinstance.py:1165} INFO - Dependencies all met for <TaskInstance: etl_solar.storage.save_weather_data manual__2022-12-11T08:17:00.192133+00:00 [queued]>
[2022-12-11T08:18:03.898+0000] {taskinstance.py:1165} INFO - Dependencies all met for <TaskInstance: etl_solar.storage.save_weather_data manual__2022-12-11T08:17:00.192133+00:00 [queued]>
[2022-12-11T08:18:03.900+0000] {taskinstance.py:1362} INFO - 
--------------------------------------------------------------------------------
[2022-12-11T08:18:03.901+0000] {taskinstance.py:1363} INFO - Starting attempt 1 of 1
[2022-12-11T08:18:03.903+0000] {taskinstance.py:1364} INFO - 
--------------------------------------------------------------------------------
[2022-12-11T08:18:03.981+0000] {taskinstance.py:1383} INFO - Executing <Task(PythonOperator): storage.save_weather_data> on 2022-12-11 08:17:00.192133+00:00
[2022-12-11T08:18:03.996+0000] {standard_task_runner.py:55} INFO - Started process 267 to run task
[2022-12-11T08:18:04.009+0000] {standard_task_runner.py:82} INFO - Running: ['***', 'tasks', 'run', 'etl_solar', 'storage.save_weather_data', 'manual__2022-12-11T08:17:00.192133+00:00', '--job-id', '65', '--raw', '--subdir', 'DAGS_FOLDER/dag_preprocess.py', '--cfg-path', '/tmp/tmplkh9zugd']
[2022-12-11T08:18:04.017+0000] {standard_task_runner.py:83} INFO - Job 65: Subtask storage.save_weather_data
[2022-12-11T08:18:04.336+0000] {task_command.py:376} INFO - Running <TaskInstance: etl_solar.storage.save_weather_data manual__2022-12-11T08:17:00.192133+00:00 [running]> on host 01c108b234e9
[2022-12-11T08:18:04.762+0000] {taskinstance.py:1592} INFO - Exporting the following env vars:
AIRFLOW_CTX_DAG_OWNER=***
AIRFLOW_CTX_DAG_ID=etl_solar
AIRFLOW_CTX_TASK_ID=storage.save_weather_data
AIRFLOW_CTX_EXECUTION_DATE=2022-12-11T08:17:00.192133+00:00
AIRFLOW_CTX_TRY_NUMBER=1
AIRFLOW_CTX_DAG_RUN_ID=manual__2022-12-11T08:17:00.192133+00:00
[2022-12-11T08:18:04.766+0000] {taskinstance.py:1851} ERROR - Task failed with exception
Traceback (most recent call last):
  File "/home/airflow/.local/lib/python3.7/site-packages/airflow/operators/python.py", line 175, in execute
    return_value = self.execute_callable()
  File "/home/airflow/.local/lib/python3.7/site-packages/airflow/operators/python.py", line 193, in execute_callable
    return self.python_callable(*self.op_args, **self.op_kwargs)
  File "/opt/airflow/dags/groups/group_storage.py", line 16, in save_to_google_stroage
    bucket=context['bucket']
KeyError: 'bucket'
[2022-12-11T08:18:04.827+0000] {taskinstance.py:1406} INFO - Marking task as FAILED. dag_id=etl_solar, task_id=storage.save_weather_data, execution_date=20221211T081700, start_date=20221211T081803, end_date=20221211T081804
[2022-12-11T08:18:04.879+0000] {standard_task_runner.py:105} ERROR - Failed to execute job 65 for task storage.save_weather_data ('bucket'; 267)
[2022-12-11T08:18:04.945+0000] {local_task_job.py:164} INFO - Task exited with return code 1
[2022-12-11T08:18:05.105+0000] {local_task_job.py:273} INFO - 0 downstream tasks scheduled from follow-on schedule check
