[2022-11-25 03:52:15,763] {taskinstance.py:1159} INFO - Dependencies all met for <TaskInstance: etl_solar.checkfiles.check_solar_table scheduled__2022-11-24T00:00:00+00:00 [queued]>
[2022-11-25 03:52:15,802] {taskinstance.py:1159} INFO - Dependencies all met for <TaskInstance: etl_solar.checkfiles.check_solar_table scheduled__2022-11-24T00:00:00+00:00 [queued]>
[2022-11-25 03:52:15,802] {taskinstance.py:1356} INFO - 
--------------------------------------------------------------------------------
[2022-11-25 03:52:15,803] {taskinstance.py:1357} INFO - Starting attempt 1 of 1
[2022-11-25 03:52:15,803] {taskinstance.py:1358} INFO - 
--------------------------------------------------------------------------------
[2022-11-25 03:52:15,881] {taskinstance.py:1377} INFO - Executing <Task(MySqlOperator): checkfiles.check_solar_table> on 2022-11-24 00:00:00+00:00
[2022-11-25 03:52:15,895] {standard_task_runner.py:52} INFO - Started process 71 to run task
[2022-11-25 03:52:15,902] {standard_task_runner.py:79} INFO - Running: ['***', 'tasks', 'run', 'etl_solar', 'checkfiles.check_solar_table', 'scheduled__2022-11-24T00:00:00+00:00', '--job-id', '270', '--raw', '--subdir', 'DAGS_FOLDER/dag_preprocess.py', '--cfg-path', '/tmp/tmp3_w77g6c', '--error-file', '/tmp/tmpska0_v0g']
[2022-11-25 03:52:15,906] {standard_task_runner.py:80} INFO - Job 270: Subtask checkfiles.check_solar_table
[2022-11-25 03:52:15,943] {warnings.py:110} WARNING - /home/***/.local/lib/python3.7/site-packages/***/configuration.py:470: DeprecationWarning: The sql_alchemy_conn option in [core] has been moved to the sql_alchemy_conn option in [database] - the old setting has been used, but please update your config.
  option = self._get_environment_variables(deprecated_key, deprecated_section, key, section)

[2022-11-25 03:52:16,162] {task_command.py:369} INFO - Running <TaskInstance: etl_solar.checkfiles.check_solar_table scheduled__2022-11-24T00:00:00+00:00 [running]> on host 8a647070b091
[2022-11-25 03:52:16,548] {taskinstance.py:1571} INFO - Exporting the following env vars:
AIRFLOW_CTX_DAG_OWNER=***
AIRFLOW_CTX_DAG_ID=etl_solar
AIRFLOW_CTX_TASK_ID=checkfiles.check_solar_table
AIRFLOW_CTX_EXECUTION_DATE=2022-11-24T00:00:00+00:00
AIRFLOW_CTX_TRY_NUMBER=1
AIRFLOW_CTX_DAG_RUN_ID=scheduled__2022-11-24T00:00:00+00:00
[2022-11-25 03:52:16,557] {mysql.py:82} INFO - Executing: 


CREATE TABLE IF NOT EXISTS geography(
                locdate VARCHAR(40),
                location VARCHAR(40),
                updated_date CHAR(10),
                altitudeMeridian VARCHAR(13),
                altitude_09 VARCHAR(20),
                altitude_12 VARCHAR(20),
                altitude_15 VARCHAR(20),
                altitude_18 VARCHAR(20),
                azimuth_09 VARCHAR(20),
                azimuth_12 VARCHAR(20),
                azimuth_15 VARCHAR(20),
                azimuth_18 VARCHAR(20),
                primary key(locdate,location))
[2022-11-25 03:52:16,627] {base.py:68} INFO - Using connection ID 'mysql_solar' for task execution.
[2022-11-25 03:52:17,073] {local_task_job.py:84} ERROR - Received SIGTERM. Terminating subprocesses
[2022-11-25 03:52:17,080] {process_utils.py:129} INFO - Sending Signals.SIGTERM to group 71. PIDs of all processes in the group: [71]
[2022-11-25 03:52:17,086] {process_utils.py:80} INFO - Sending the signal Signals.SIGTERM to group 71
[2022-11-25 03:52:18,748] {taskinstance.py:1541} ERROR - Received SIGTERM. Terminating subprocesses.
[2022-11-25 03:52:18,777] {taskinstance.py:1889} ERROR - Task failed with exception
Traceback (most recent call last):
  File "/home/airflow/.local/lib/python3.7/site-packages/airflow/models/taskinstance.py", line 1598, in _execute_task_with_callbacks
    result = self._execute_task(context, task_orig)
  File "/home/airflow/.local/lib/python3.7/site-packages/airflow/models/taskinstance.py", line 1659, in _execute_task
    result = execute_callable(context=context)
  File "/home/airflow/.local/lib/python3.7/site-packages/airflow/providers/mysql/operators/mysql.py", line 84, in execute
    hook.run(self.sql, autocommit=self.autocommit, parameters=self.parameters)
  File "/home/airflow/.local/lib/python3.7/site-packages/airflow/hooks/dbapi.py", line 181, in run
    with closing(self.get_conn()) as conn:
  File "/home/airflow/.local/lib/python3.7/site-packages/airflow/providers/mysql/hooks/mysql.py", line 166, in get_conn
    return MySQLdb.connect(**conn_config)
  File "/home/airflow/.local/lib/python3.7/site-packages/MySQLdb/__init__.py", line 123, in Connect
    return Connection(*args, **kwargs)
  File "/home/airflow/.local/lib/python3.7/site-packages/MySQLdb/connections.py", line 185, in __init__
    super().__init__(*args, **kwargs2)
MySQLdb._exceptions.OperationalError: (2003, "Can't connect to MySQL server on 'host.docker.internal:3306' (111)")

During handling of the above exception, another exception occurred:

Traceback (most recent call last):
  File "/home/airflow/.local/lib/python3.7/site-packages/airflow/models/taskinstance.py", line 1451, in _run_raw_task
    self._execute_task_with_callbacks(context, test_mode)
  File "/home/airflow/.local/lib/python3.7/site-packages/airflow/models/taskinstance.py", line 1598, in _execute_task_with_callbacks
    result = self._execute_task(context, task_orig)
  File "/home/airflow/.local/lib/python3.7/site-packages/airflow/models/taskinstance.py", line 1543, in signal_handler
    raise AirflowException("Task received SIGTERM signal")
airflow.exceptions.AirflowException: Task received SIGTERM signal
[2022-11-25 03:52:18,794] {taskinstance.py:1400} INFO - Marking task as FAILED. dag_id=etl_solar, task_id=checkfiles.check_solar_table, execution_date=20221124T000000, start_date=20221125T035215, end_date=20221125T035218
[2022-11-25 03:52:18,822] {standard_task_runner.py:97} ERROR - Failed to execute job 270 for task checkfiles.check_solar_table (Task received SIGTERM signal; 71)
[2022-11-25 03:52:18,868] {process_utils.py:75} INFO - Process psutil.Process(pid=71, status='terminated', exitcode=1, started='03:52:15') (71) terminated with exit code 1
[2022-11-25 03:52:18,869] {local_task_job.py:156} INFO - Task exited with return code 143
