[2022-11-22 05:05:03,632] {taskinstance.py:1159} INFO - Dependencies all met for <TaskInstance: etl_solar.weather_transform.preprocess_weather manual__2022-11-22T05:04:43.707828+00:00 [queued]>
[2022-11-22 05:05:03,678] {taskinstance.py:1159} INFO - Dependencies all met for <TaskInstance: etl_solar.weather_transform.preprocess_weather manual__2022-11-22T05:04:43.707828+00:00 [queued]>
[2022-11-22 05:05:03,679] {taskinstance.py:1356} INFO - 
--------------------------------------------------------------------------------
[2022-11-22 05:05:03,680] {taskinstance.py:1357} INFO - Starting attempt 1 of 1
[2022-11-22 05:05:03,681] {taskinstance.py:1358} INFO - 
--------------------------------------------------------------------------------
[2022-11-22 05:05:03,747] {taskinstance.py:1377} INFO - Executing <Task(PythonOperator): weather_transform.preprocess_weather> on 2022-11-22 05:04:43.707828+00:00
[2022-11-22 05:05:03,761] {standard_task_runner.py:52} INFO - Started process 417 to run task
[2022-11-22 05:05:03,778] {standard_task_runner.py:79} INFO - Running: ['***', 'tasks', 'run', 'etl_solar', 'weather_transform.preprocess_weather', 'manual__2022-11-22T05:04:43.707828+00:00', '--job-id', '220', '--raw', '--subdir', 'DAGS_FOLDER/dag_preprocess.py', '--cfg-path', '/tmp/tmp9hc9f5fz', '--error-file', '/tmp/tmpd6todd7f']
[2022-11-22 05:05:03,783] {standard_task_runner.py:80} INFO - Job 220: Subtask weather_transform.preprocess_weather
[2022-11-22 05:05:04,107] {task_command.py:369} INFO - Running <TaskInstance: etl_solar.weather_transform.preprocess_weather manual__2022-11-22T05:04:43.707828+00:00 [running]> on host 8a647070b091
[2022-11-22 05:05:04,528] {taskinstance.py:1571} INFO - Exporting the following env vars:
AIRFLOW_CTX_DAG_OWNER=***
AIRFLOW_CTX_DAG_ID=etl_solar
AIRFLOW_CTX_TASK_ID=weather_transform.preprocess_weather
AIRFLOW_CTX_EXECUTION_DATE=2022-11-22T05:04:43.707828+00:00
AIRFLOW_CTX_TRY_NUMBER=1
AIRFLOW_CTX_DAG_RUN_ID=manual__2022-11-22T05:04:43.707828+00:00
[2022-11-22 05:05:04,593] {taskinstance.py:1889} ERROR - Task failed with exception
Traceback (most recent call last):
  File "/home/airflow/.local/lib/python3.7/site-packages/airflow/operators/python.py", line 171, in execute
    return_value = self.execute_callable()
  File "/home/airflow/.local/lib/python3.7/site-packages/airflow/operators/python.py", line 189, in execute_callable
    return self.python_callable(*self.op_args, **self.op_kwargs)
  File "/opt/airflow/dags/preprocess/preprocess.py", line 55, in weather_preprocess
    df=interpolation(df=df,col="Forecast_Time")
  File "/opt/airflow/dags/preprocess/preprocess.py", line 38, in interpolation
    freq='H')
UnboundLocalError: local variable 'new_df' referenced before assignment
[2022-11-22 05:05:04,643] {taskinstance.py:1400} INFO - Marking task as FAILED. dag_id=etl_solar, task_id=weather_transform.preprocess_weather, execution_date=20221122T050443, start_date=20221122T050503, end_date=20221122T050504
[2022-11-22 05:05:04,692] {standard_task_runner.py:97} ERROR - Failed to execute job 220 for task weather_transform.preprocess_weather (local variable 'new_df' referenced before assignment; 417)
[2022-11-22 05:05:04,756] {local_task_job.py:156} INFO - Task exited with return code 1
[2022-11-22 05:05:04,921] {local_task_job.py:273} INFO - 0 downstream tasks scheduled from follow-on schedule check
