[2022-11-20 11:44:28,353] {taskinstance.py:1159} INFO - Dependencies all met for <TaskInstance: etl_solar.load_files.extract_weather_info manual__2022-11-20T11:44:24.699974+00:00 [queued]>
[2022-11-20 11:44:28,367] {taskinstance.py:1159} INFO - Dependencies all met for <TaskInstance: etl_solar.load_files.extract_weather_info manual__2022-11-20T11:44:24.699974+00:00 [queued]>
[2022-11-20 11:44:28,367] {taskinstance.py:1356} INFO - 
--------------------------------------------------------------------------------
[2022-11-20 11:44:28,368] {taskinstance.py:1357} INFO - Starting attempt 1 of 1
[2022-11-20 11:44:28,368] {taskinstance.py:1358} INFO - 
--------------------------------------------------------------------------------
[2022-11-20 11:44:28,387] {taskinstance.py:1377} INFO - Executing <Task(PythonOperator): load_files.extract_weather_info> on 2022-11-20 11:44:24.699974+00:00
[2022-11-20 11:44:28,392] {standard_task_runner.py:52} INFO - Started process 158 to run task
[2022-11-20 11:44:28,396] {standard_task_runner.py:79} INFO - Running: ['***', 'tasks', 'run', 'etl_solar', 'load_files.extract_weather_info', 'manual__2022-11-20T11:44:24.699974+00:00', '--job-id', '32', '--raw', '--subdir', 'DAGS_FOLDER/dag_preprocess.py', '--cfg-path', '/tmp/tmp_fqzn3nq', '--error-file', '/tmp/tmp_oohfwnf']
[2022-11-20 11:44:28,398] {standard_task_runner.py:80} INFO - Job 32: Subtask load_files.extract_weather_info
[2022-11-20 11:44:28,465] {task_command.py:369} INFO - Running <TaskInstance: etl_solar.load_files.extract_weather_info manual__2022-11-20T11:44:24.699974+00:00 [running]> on host 82103fd5e777
[2022-11-20 11:44:28,559] {taskinstance.py:1571} INFO - Exporting the following env vars:
AIRFLOW_CTX_DAG_OWNER=***
AIRFLOW_CTX_DAG_ID=etl_solar
AIRFLOW_CTX_TASK_ID=load_files.extract_weather_info
AIRFLOW_CTX_EXECUTION_DATE=2022-11-20T11:44:24.699974+00:00
AIRFLOW_CTX_TRY_NUMBER=1
AIRFLOW_CTX_DAG_RUN_ID=manual__2022-11-20T11:44:24.699974+00:00
[2022-11-20 11:44:28,570] {base.py:68} INFO - Using connection ID 'mysql_solar' for task execution.
[2022-11-20 11:44:28,601] {taskinstance.py:1889} ERROR - Task failed with exception
Traceback (most recent call last):
  File "/home/airflow/.local/lib/python3.7/site-packages/airflow/operators/python.py", line 171, in execute
    return_value = self.execute_callable()
  File "/home/airflow/.local/lib/python3.7/site-packages/airflow/operators/python.py", line 189, in execute_callable
    return self.python_callable(*self.op_args, **self.op_kwargs)
  File "/opt/airflow/dags/preprocess/connection.py", line 13, in inner_function
    return function(conn,cursor,**kwargs)
TypeError: save_data() got multiple values for argument 'conn'
[2022-11-20 11:44:28,616] {taskinstance.py:1400} INFO - Marking task as FAILED. dag_id=etl_solar, task_id=load_files.extract_weather_info, execution_date=20221120T114424, start_date=20221120T114428, end_date=20221120T114428
[2022-11-20 11:44:28,628] {standard_task_runner.py:97} ERROR - Failed to execute job 32 for task load_files.extract_weather_info (save_data() got multiple values for argument 'conn'; 158)
[2022-11-20 11:44:28,649] {local_task_job.py:156} INFO - Task exited with return code 1
[2022-11-20 11:44:28,686] {local_task_job.py:273} INFO - 0 downstream tasks scheduled from follow-on schedule check
