[2022-11-22 04:59:50,983] {taskinstance.py:1159} INFO - Dependencies all met for <TaskInstance: etl_solar.weather_transform.preprocess_weather manual__2022-11-22T04:59:28.752525+00:00 [queued]>
[2022-11-22 04:59:51,027] {taskinstance.py:1159} INFO - Dependencies all met for <TaskInstance: etl_solar.weather_transform.preprocess_weather manual__2022-11-22T04:59:28.752525+00:00 [queued]>
[2022-11-22 04:59:51,029] {taskinstance.py:1356} INFO - 
--------------------------------------------------------------------------------
[2022-11-22 04:59:51,030] {taskinstance.py:1357} INFO - Starting attempt 1 of 1
[2022-11-22 04:59:51,031] {taskinstance.py:1358} INFO - 
--------------------------------------------------------------------------------
[2022-11-22 04:59:51,096] {taskinstance.py:1377} INFO - Executing <Task(PythonOperator): weather_transform.preprocess_weather> on 2022-11-22 04:59:28.752525+00:00
[2022-11-22 04:59:51,110] {standard_task_runner.py:52} INFO - Started process 346 to run task
[2022-11-22 04:59:51,129] {standard_task_runner.py:79} INFO - Running: ['***', 'tasks', 'run', 'etl_solar', 'weather_transform.preprocess_weather', 'manual__2022-11-22T04:59:28.752525+00:00', '--job-id', '200', '--raw', '--subdir', 'DAGS_FOLDER/dag_preprocess.py', '--cfg-path', '/tmp/tmp1nz74pei', '--error-file', '/tmp/tmp98dguicm']
[2022-11-22 04:59:51,134] {standard_task_runner.py:80} INFO - Job 200: Subtask weather_transform.preprocess_weather
[2022-11-22 04:59:51,445] {task_command.py:369} INFO - Running <TaskInstance: etl_solar.weather_transform.preprocess_weather manual__2022-11-22T04:59:28.752525+00:00 [running]> on host 8a647070b091
[2022-11-22 04:59:51,888] {taskinstance.py:1571} INFO - Exporting the following env vars:
AIRFLOW_CTX_DAG_OWNER=***
AIRFLOW_CTX_DAG_ID=etl_solar
AIRFLOW_CTX_TASK_ID=weather_transform.preprocess_weather
AIRFLOW_CTX_EXECUTION_DATE=2022-11-22T04:59:28.752525+00:00
AIRFLOW_CTX_TRY_NUMBER=1
AIRFLOW_CTX_DAG_RUN_ID=manual__2022-11-22T04:59:28.752525+00:00
[2022-11-22 04:59:51,898] {taskinstance.py:1889} ERROR - Task failed with exception
Traceback (most recent call last):
  File "/home/airflow/.local/lib/python3.7/site-packages/airflow/operators/python.py", line 171, in execute
    return_value = self.execute_callable()
  File "/home/airflow/.local/lib/python3.7/site-packages/airflow/operators/python.py", line 189, in execute_callable
    return self.python_callable(*self.op_args, **self.op_kwargs)
  File "/opt/airflow/dags/preprocess/preprocess.py", line 46, in weather_preprocess
    df=pd.read_csv(context['start_path'])
KeyError: 'start_path'
[2022-11-22 04:59:51,958] {taskinstance.py:1400} INFO - Marking task as FAILED. dag_id=etl_solar, task_id=weather_transform.preprocess_weather, execution_date=20221122T045928, start_date=20221122T045950, end_date=20221122T045951
[2022-11-22 04:59:52,006] {standard_task_runner.py:97} ERROR - Failed to execute job 200 for task weather_transform.preprocess_weather ('start_path'; 346)
[2022-11-22 04:59:52,028] {local_task_job.py:156} INFO - Task exited with return code 1
[2022-11-22 04:59:52,197] {local_task_job.py:273} INFO - 0 downstream tasks scheduled from follow-on schedule check
